2025-02-28 12:22:29,063 INFO    StreamThr :107166 [internal.py:wandb_internal():88] W&B internal server running at pid: 107166, started at: 2025-02-28 12:22:29.062142
2025-02-28 12:22:29,064 DEBUG   HandlerThread:107166 [handler.py:handle_request():138] handle_request: status
2025-02-28 12:22:29,066 DEBUG   SenderThread:107166 [sender.py:send_request():317] send_request: status
2025-02-28 12:22:29,067 DEBUG   SenderThread:107166 [sender.py:send():303] send: header
2025-02-28 12:22:29,067 INFO    WriterThread:107166 [datastore.py:open_for_write():75] open: /home/yang1641/PINNACLE/pinnacle/wandb/run-20250228_122229-cli9nj63/run-cli9nj63.wandb
2025-02-28 12:22:29,123 DEBUG   SenderThread:107166 [sender.py:send():303] send: run
2025-02-28 12:22:29,244 ERROR   SenderThread:107166 [internal_api.py:execute():216] 403 response executing GraphQL.
2025-02-28 12:22:29,244 ERROR   SenderThread:107166 [internal_api.py:execute():217] {"errors":[{"message":"permission denied","path":["upsertBucket"],"extensions":{"code":"PERMISSION_ERROR"}}],"data":{"upsertBucket":null}}
2025-02-28 12:22:30,123 INFO    WriterThread:107166 [datastore.py:close():279] close: /home/yang1641/PINNACLE/pinnacle/wandb/run-20250228_122229-cli9nj63/run-cli9nj63.wandb
2025-02-28 12:22:30,124 INFO    HandlerThread:107166 [handler.py:finish():814] shutting down handler
2025-02-28 12:22:30,126 ERROR   StreamThr :107166 [internal.py:wandb_internal():163] Thread SenderThread:
Traceback (most recent call last):
  File "/home/yang1641/.conda/envs/cent7/2024.02-py311/pinnacle/lib/python3.8/site-packages/wandb/sdk/lib/retry.py", line 113, in __call__
    result = self._call_fn(*args, **kwargs)
  File "/home/yang1641/.conda/envs/cent7/2024.02-py311/pinnacle/lib/python3.8/site-packages/wandb/sdk/internal/internal_api.py", line 213, in execute
    return self.client.execute(*args, **kwargs)  # type: ignore
  File "/home/yang1641/.conda/envs/cent7/2024.02-py311/pinnacle/lib/python3.8/site-packages/wandb/vendor/gql-0.2.0/wandb_gql/client.py", line 52, in execute
    result = self._get_result(document, *args, **kwargs)
  File "/home/yang1641/.conda/envs/cent7/2024.02-py311/pinnacle/lib/python3.8/site-packages/wandb/vendor/gql-0.2.0/wandb_gql/client.py", line 60, in _get_result
    return self.transport.execute(document, *args, **kwargs)
  File "/home/yang1641/.conda/envs/cent7/2024.02-py311/pinnacle/lib/python3.8/site-packages/wandb/vendor/gql-0.2.0/wandb_gql/transport/requests.py", line 39, in execute
    request.raise_for_status()
  File "/home/yang1641/.conda/envs/cent7/2024.02-py311/pinnacle/lib/python3.8/site-packages/requests/models.py", line 1021, in raise_for_status
    raise HTTPError(http_error_msg, response=self)
requests.exceptions.HTTPError: 403 Client Error: Forbidden for url: https://api.wandb.ai/graphql

During handling of the above exception, another exception occurred:

Traceback (most recent call last):
  File "/home/yang1641/.conda/envs/cent7/2024.02-py311/pinnacle/lib/python3.8/site-packages/wandb/apis/normalize.py", line 26, in wrapper
    return func(*args, **kwargs)
  File "/home/yang1641/.conda/envs/cent7/2024.02-py311/pinnacle/lib/python3.8/site-packages/wandb/sdk/internal/internal_api.py", line 1474, in upsert_run
    response = self.gql(
  File "/home/yang1641/.conda/envs/cent7/2024.02-py311/pinnacle/lib/python3.8/site-packages/wandb/sdk/lib/retry.py", line 129, in __call__
    retry_timedelta_triggered = check_retry_fn(e)
  File "/home/yang1641/.conda/envs/cent7/2024.02-py311/pinnacle/lib/python3.8/site-packages/wandb/util.py", line 1030, in check_retry_fn
    return fallback_retry_fn(e)
  File "/home/yang1641/.conda/envs/cent7/2024.02-py311/pinnacle/lib/python3.8/site-packages/wandb/util.py", line 977, in no_retry_auth
    raise CommError("Permission denied, ask the project owner to grant you access")
wandb.errors.CommError: Permission denied, ask the project owner to grant you access

During handling of the above exception, another exception occurred:

Traceback (most recent call last):
  File "/home/yang1641/.conda/envs/cent7/2024.02-py311/pinnacle/lib/python3.8/site-packages/wandb/sdk/internal/internal_util.py", line 50, in run
    self._run()
  File "/home/yang1641/.conda/envs/cent7/2024.02-py311/pinnacle/lib/python3.8/site-packages/wandb/sdk/internal/internal_util.py", line 101, in _run
    self._process(record)
  File "/home/yang1641/.conda/envs/cent7/2024.02-py311/pinnacle/lib/python3.8/site-packages/wandb/sdk/internal/internal.py", line 308, in _process
    self._sm.send(record)
  File "/home/yang1641/.conda/envs/cent7/2024.02-py311/pinnacle/lib/python3.8/site-packages/wandb/sdk/internal/sender.py", line 305, in send
    send_handler(record)
  File "/home/yang1641/.conda/envs/cent7/2024.02-py311/pinnacle/lib/python3.8/site-packages/wandb/sdk/internal/sender.py", line 797, in send_run
    self._init_run(run, config_value_dict)
  File "/home/yang1641/.conda/envs/cent7/2024.02-py311/pinnacle/lib/python3.8/site-packages/wandb/sdk/internal/sender.py", line 823, in _init_run
    server_run, inserted, server_messages = self._api.upsert_run(
  File "/home/yang1641/.conda/envs/cent7/2024.02-py311/pinnacle/lib/python3.8/site-packages/wandb/apis/normalize.py", line 62, in wrapper
    raise CommError(message, err).with_traceback(sys.exc_info()[2])
  File "/home/yang1641/.conda/envs/cent7/2024.02-py311/pinnacle/lib/python3.8/site-packages/wandb/apis/normalize.py", line 26, in wrapper
    return func(*args, **kwargs)
  File "/home/yang1641/.conda/envs/cent7/2024.02-py311/pinnacle/lib/python3.8/site-packages/wandb/sdk/internal/internal_api.py", line 1474, in upsert_run
    response = self.gql(
  File "/home/yang1641/.conda/envs/cent7/2024.02-py311/pinnacle/lib/python3.8/site-packages/wandb/sdk/lib/retry.py", line 129, in __call__
    retry_timedelta_triggered = check_retry_fn(e)
  File "/home/yang1641/.conda/envs/cent7/2024.02-py311/pinnacle/lib/python3.8/site-packages/wandb/util.py", line 1030, in check_retry_fn
    return fallback_retry_fn(e)
  File "/home/yang1641/.conda/envs/cent7/2024.02-py311/pinnacle/lib/python3.8/site-packages/wandb/util.py", line 977, in no_retry_auth
    raise CommError("Permission denied, ask the project owner to grant you access")
wandb.errors.CommError: Permission denied, ask the project owner to grant you access
